<?xml version="1.0" encoding="utf-8"?>
<!-- This URDF was automatically created by SolidWorks to URDF Exporter! Originally created by Stephen Brawner (brawner@gmail.com) 
     Commit Version: 1.6.0-4-g7f85cfe  Build Version: 1.6.7995.38578
     For more information, please see http://wiki.ros.org/sw_urdf_exporter -->
<robot
  name="2D_Tiltrotr">
  <link
    name="base">
    <inertial>
      <origin
        xyz="1.0149 -0.001514 -0.040155"
        rpy="0 0 0" />
      <mass
        value="0.060391" />
      <inertia
        ixx="2.1448E-05"
        ixy="-3.9246E-08"
        ixz="-1.6256E-09"
        iyy="1.4542E-05"
        iyz="-2.6219E-06"
        izz="1.6878E-05" />
    </inertial>
    <visual>
      <origin
        xyz="0 0 0"
        rpy="0 0 0" />
      <geometry>
        <mesh
          filename="package://URDF/meshes/base.STL" />
      </geometry>
      <material
        name="">
        <color
          rgba="0.79216 0.81961 0.93333 1" />
      </material>
    </visual>
    <collision>
      <origin
        xyz="0 0 0"
        rpy="0 0 0" />
      <geometry>
        <mesh
          filename="package://URDF/meshes/base.STL" />
      </geometry>
    </collision>
  </link>
  <link
    name="link1">
    <inertial>
      <origin
        xyz="0.50545 0.021467 -0.00047344"
        rpy="0 0 0" />
      <mass
        value="0.049636" />
      <inertia
        ixx="7.018E-06"
        ixy="-0.00010004"
        ixz="-5.2581E-07"
        iyy="0.002358"
        iyz="-2.2334E-08"
        izz="0.0023612" />
    </inertial>
    <visual>
      <origin
        xyz="0 0 0"
        rpy="0 0 0" />
      <geometry>
        <mesh
          filename="package://URDF/meshes/link1.STL" />
      </geometry>
      <material
        name="">
        <color
          rgba="0.79216 0.81961 0.93333 1" />
      </material>
    </visual>
    <collision>
      <origin
        xyz="0 0 0"
        rpy="0 0 0" />
      <geometry>
        <mesh
          filename="package://URDF/meshes/link1.STL" />
      </geometry>
    </collision>
  </link>
  <joint
    name="revolute0"
    type="revolute">
    <origin
      xyz="1.015 0 0"
      rpy="1.5708 0 0" />
    <parent
      link="base" />
    <child
      link="link1" />
    <axis
      xyz="0 0 1" />
    <limit
      lower="-1.3"
      upper="4.3"
      effort="0"
      velocity="0" />
  </joint>
  <link
    name="link2">
    <inertial>
      <origin
        xyz="-0.50472 0.0046682 3.1062E-05"
        rpy="0 0 0" />
      <mass
        value="0.042551" />
      <inertia
        ixx="3.7566E-06"
        ixy="-6.4217E-05"
        ixz="2.3879E-14"
        iyy="0.0023562"
        iyz="3.419E-13"
        izz="0.0023588" />
    </inertial>
    <visual>
      <origin
        xyz="0 0 0"
        rpy="0 0 0" />
      <geometry>
        <mesh
          filename="package://URDF/meshes/link2.STL" />
      </geometry>
      <material
        name="">
        <color
          rgba="0.79216 0.81961 0.93333 1" />
      </material>
    </visual>
    <collision>
      <origin
        xyz="0 0 0"
        rpy="0 0 0" />
      <geometry>
        <mesh
          filename="package://URDF/meshes/link2.STL" />
      </geometry>
    </collision>
  </link>
  <joint
    name="revolute1"
    type="revolute">
    <origin
      xyz="1.0291 0.04371 0"
      rpy="0 0 0" />
    <parent
      link="link1" />
    <child
      link="link2" />
    <axis
      xyz="0 0 -1" />
    <limit
      lower="-3.14"
      upper="0"
      effort="0"
      velocity="0" />
  </joint>
  <link
    name="fuse">
    <inertial>
      <origin
        xyz="0.041733 0.042057 -0.0013155"
        rpy="0 0 0" />
      <mass
        value="0.19397" />
      <inertia
        ixx="8.2497E-05"
        ixy="-0.00019967"
        ixz="3.3211E-08"
        iyy="0.0013162"
        iyz="-5.7312E-09"
        izz="0.0013795" />
    </inertial>
    <visual>
      <origin
        xyz="0 0 0"
        rpy="0 0 0" />
      <geometry>
        <mesh
          filename="package://URDF/meshes/fuse.STL" />
      </geometry>
      <material
        name="">
        <color
          rgba="0.79216 0.81961 0.93333 1" />
      </material>
    </visual>
    <collision>
      <origin
        xyz="0 0 0"
        rpy="0 0 0" />
      <geometry>
        <mesh
          filename="package://URDF/meshes/fuse.STL" />
      </geometry>
    </collision>
  </link>
  <joint
    name="revolute2"
    type="revolute">
    <origin
      xyz="-1.0307 0.0095324 0"
      rpy="0 0 0" />
    <parent
      link="link2" />
    <child
      link="fuse" />
    <axis
      xyz="0 0 1" />
    <limit
      lower="-0.785398"
      upper="1.57"
      effort="0"
      velocity="0" />
  </joint>
  <link
    name="rotor">
    <inertial>
      <origin
        xyz="0.00019334 0.010035 0.0014178"
        rpy="0 0 0" />
      <mass
        value="0.023971" />
      <inertia
        ixx="3.7206E-05"
        ixy="1.3271E-08"
        ixz="1.456E-08"
        iyy="3.8648E-05"
        iyz="-4.4238E-09"
        izz="1.9507E-06" />
    </inertial>
    <visual>
      <origin
        xyz="0 0 0"
        rpy="0 0 0" />
      <geometry>
        <mesh
          filename="package://URDF/meshes/rotor.STL" />
      </geometry>
      <material
        name="">
        <color
          rgba="0.79216 0.81961 0.93333 1" />
      </material>
    </visual>
    <collision>
      <origin
        xyz="0 0 0"
        rpy="0 0 0" />
      <geometry>
        <mesh
          filename="package://URDF/meshes/rotor.STL" />
      </geometry>
    </collision>
  </link>
  <joint
    name="revolute3"
    type="revolute">
    <origin
      xyz="0.035 0.093675 0"
      rpy="0 0 0" />
    <parent
      link="fuse" />
    <child
      link="rotor" />
    <axis
      xyz="0 0 1" />
    <limit
      lower="-1"
      upper="1"
      effort="0"
      velocity="0" />
  </joint>
</robot>